Traceback (most recent call last):
  File "/home/alexbui/anaconda3/lib/python3.8/site-packages/jupyter_cache/executors/utils.py", line 51, in single_nb_execution
    executenb(
  File "/home/alexbui/anaconda3/lib/python3.8/site-packages/nbclient/client.py", line 1112, in execute
    return NotebookClient(nb=nb, resources=resources, km=km, **kwargs).execute()
  File "/home/alexbui/anaconda3/lib/python3.8/site-packages/nbclient/util.py", line 74, in wrapped
    return just_run(coro(*args, **kwargs))
  File "/home/alexbui/anaconda3/lib/python3.8/site-packages/nbclient/util.py", line 53, in just_run
    return loop.run_until_complete(coro)
  File "/home/alexbui/anaconda3/lib/python3.8/asyncio/base_events.py", line 616, in run_until_complete
    return future.result()
  File "/home/alexbui/anaconda3/lib/python3.8/site-packages/nbclient/client.py", line 553, in async_execute
    await self.async_execute_cell(
  File "/home/alexbui/anaconda3/lib/python3.8/site-packages/nbclient/client.py", line 857, in async_execute_cell
    self._check_raise_for_error(cell, exec_reply)
  File "/home/alexbui/anaconda3/lib/python3.8/site-packages/nbclient/client.py", line 760, in _check_raise_for_error
    raise CellExecutionError.from_cell_and_msg(cell, exec_reply_content)
nbclient.exceptions.CellExecutionError: An error occurred while executing the following cell:
------------------
dataset1 = concat_dataframe(air_weather2, 1)
training1 = dataset1[dataset1['datetime'] <= "2017-12-31 23:00:00"]
training1.drop(drp_columns, axis=1, inplace=True)
testing1 = dataset1[dataset1['datetime'] > "2017-12-31 23:00:00"]
testing1.drop(drp_columns, axis=1, inplace=True)
X1_train, y1_train = training1.drop(target, axis=1), training1['pm2_5_conc']
X1_test, y1_test = testing1.drop(target, axis=1), testing1['pm2_5_conc']
------------------

[0;31m---------------------------------------------------------------------------[0m
[0;31mNameError[0m                                 Traceback (most recent call last)
[0;32m<ipython-input-23-b3e90dfa8e13>[0m in [0;36m<module>[0;34m[0m
[1;32m      1[0m [0mdataset1[0m [0;34m=[0m [0mconcat_dataframe[0m[0;34m([0m[0mair_weather2[0m[0;34m,[0m [0;36m1[0m[0;34m)[0m[0;34m[0m[0;34m[0m[0m
[1;32m      2[0m [0mtraining1[0m [0;34m=[0m [0mdataset1[0m[0;34m[[0m[0mdataset1[0m[0;34m[[0m[0;34m'datetime'[0m[0;34m][0m [0;34m<=[0m [0;34m"2017-12-31 23:00:00"[0m[0;34m][0m[0;34m[0m[0;34m[0m[0m
[0;32m----> 3[0;31m [0mtraining1[0m[0;34m.[0m[0mdrop[0m[0;34m([0m[0mdrp_columns[0m[0;34m,[0m [0maxis[0m[0;34m=[0m[0;36m1[0m[0;34m,[0m [0minplace[0m[0;34m=[0m[0;32mTrue[0m[0;34m)[0m[0;34m[0m[0;34m[0m[0m
[0m[1;32m      4[0m [0mtesting1[0m [0;34m=[0m [0mdataset1[0m[0;34m[[0m[0mdataset1[0m[0;34m[[0m[0;34m'datetime'[0m[0;34m][0m [0;34m>[0m [0;34m"2017-12-31 23:00:00"[0m[0;34m][0m[0;34m[0m[0;34m[0m[0m
[1;32m      5[0m [0mtesting1[0m[0;34m.[0m[0mdrop[0m[0;34m([0m[0mdrp_columns[0m[0;34m,[0m [0maxis[0m[0;34m=[0m[0;36m1[0m[0;34m,[0m [0minplace[0m[0;34m=[0m[0;32mTrue[0m[0;34m)[0m[0;34m[0m[0;34m[0m[0m

[0;31mNameError[0m: name 'drp_columns' is not defined
NameError: name 'drp_columns' is not defined

